Workbook
Name Slicer_PAYEE_NAME: #N/A

Sheet Brief About Samuel Trading
C2: Case Summary | D2: Samuel Trading Company was onboarded as a trading entity dealing in spices. Initial onboarding and field verification were satisfactory. Subsequent transaction monitoring identified unusually high transaction velocity inconsistent with declared turnover. Multiple statutory notices were later received from law enforcement agencies across jurisdictions, leading to enhanced due diligence and identification of potential mule account activity.
C4: Samuel Trading Company
C6: Directors | D6: Isaac Samuel and James Samuel
C10: Documents Procured during Onboarding | D10: * Copy of MCA Certificate verified copy. *UDYAM Registration Certificate verified copy *Pan Card copy for the entity and both Individual Partners. *GST Registration Certificate verified copy.
C11: FV And Observations(Onboarding) | D11: *Branch had conducted Field Verification and observations were positive during onboarding. *The directors were involved in Trading of Spices and had clientel across the country.
C12: Annual Declared Turnover | D12: Rs.14,00,000.00
C13: Modus Operandi
C14: Statutory Notices | D14: As of 15/09/2025 Statutory Notices were received from Guntur, Madurai, Mumbai Police. The notices had requested to mark freeze in the account due to suspicious transactions observed.
C15: Suspicous transactions alerts received | D15: Yes. Bank has a team dedicated to monitoring transactions. Alerts were raised due to multiple debit and credit transactions observed in the accounts on a single day. The transactions were higher than the declared turnover. The team had requested the branch to conduct EDD and provide Inputs regarding the observations.
C16: Analysis of Transactions | D16: * The analysis of the transactions revealed that multiple debit and credit transactions were observed in the account in between 16/08/2025 and 25/08/2025. These transactions were observed within gap of few minutes on given days. *The turnover in the account was higher than declared annual turnover. *Multiple Internal debit and credit transfers were observed with entities that have already been red flagged and are under investigation. *The transaction pattern reveals strong possibility of routing fraudulent funds and suspicious mule activity.
C17: EDD and FV Observations. | D17: *Branch conducted another FV after alerts were triggered and statutory notices were received and concluded as negative. *The Shop on the location was closed. The directors were not contactable. Branch had earlier contacted the directors when suspicious transactions were observed . However, they did not disclose the details. *The neighbouring entities confirmed that both the directors were under judicial custody and the office was sealed by the Police station.
C18: Key Red Flags Observed | D18: *Turnover Mismatch * High transaction velocity *Multiple Statutory Notices received. *Directors under judicial custody. *Police Investigation Initiated.
C19: Conclusion | D19: *Basis the entire investigation conducted and statutory notices recceived it appears that the account of Samuel trading company was used for routing of fraudulent transactions. The role of the Directors in routing of these transactions cannot be ruled out. Hence, the case is being concluded as fraud perpetrated by the directors Isaac Samuel and James Samuel.
C20: Recommendations | D20: *The Fraud Intellegence Unit is requested to continue with the freeze marked in the account. *AML team is requested to file an Suspicious Transaction report. *The Branch is requested to Red flag the KYC documents of the entity and both the directors.

Sheet Transaction Details
L2: VLOOKUP | M2: XLOOKUP
A3: CUST ID | B3: ACCT NO | C3: ACCT NAME | D3: SOLID | E3: TRANSACTION AMOUNT | F3: TRANSACTION TYPE | G3: TRANSACTION DATE | H3: DEBIT | I3: CREDIT | J3: PAYEE NAME | K3: TXN REMARKS | L3: RISK LEVEL | M3: CITY
A4: 973498256 | B4: 925029911485208 | C4: THE SAMUEL TRADING COMPANY | D4: 1245 | E4: 50000 | F4: CREDIT | G4: 45840 | H4: =IF(F4="DEBIT",E4,"-") -> - | I4: 50000 | J4: OTHER | K4: DD_PROCEEDS | L4: - | M4: =_xlfn.XLOOKUP(J4,'Entity Risk Master'!$D$5:$D$8,'Entity Risk Master'!$F$5:$F$8,"-",0,1) -> -
A5: 973498256 | B5: 925029911485208 | C5: THE SAMUEL TRADING COMPANY | D5: 1245 | E5: 300 | F5: DEBIT | G5: 45885 | H5: =IF(F5="DEBIT",E5,"-") -> 300 | I5: =IF(F5="CREDIT",E5,"-") -> - | J5: OTHER | K5: BANK CHARGES | L5: - | M5: =_xlfn.XLOOKUP(J5,'Entity Risk Master'!$D$5:$D$8,'Entity Risk Master'!$F$5:$F$8,"-",0,1) -> - | R5: Exercise
A6: 973498256 | B6: 925029911485208 | C6: THE SAMUEL TRADING COMPANY | D6: 1245 | E6: 500 | F6: DEBIT | G6: 45885 | H6: =IF(F6="DEBIT",E6,"-") -> 500 | I6: =IF(F6="CREDIT",E6,"-") -> - | J6: OTHER | K6: BANK CHARGES | L6: - | M6: =_xlfn.XLOOKUP(J6,'Entity Risk Master'!$D$5:$D$8,'Entity Risk Master'!$F$5:$F$8,"-",0,1) -> -
A7: 973498256 | B7: 925029911485208 | C7: THE SAMUEL TRADING COMPANY | D7: 1245 | E7: 340 | F7: DEBIT | G7: 45885 | H7: =IF(F7="DEBIT",E7,"-") -> 340 | I7: =IF(F7="CREDIT",E7,"-") -> - | K7: NEFT DEBIT | L7: - | M7: =_xlfn.XLOOKUP(J7,'Entity Risk Master'!$D$5:$D$8,'Entity Risk Master'!$F$5:$F$8,"-",0,1) -> - | P7: 1. Use the count function to count the number of transactions for the debit and credit statements
A8: 973498256 | B8: 925029911485208 | C8: THE SAMUEL TRADING COMPANY | D8: 1245 | E8: 211 | F8: DEBIT | G8: 45885 | H8: =IF(F8="DEBIT",E8,"-") -> 211 | I8: =IF(F8="CREDIT",E8,"-") -> - | K8: NEFT DEBIT | L8: - | M8: =_xlfn.XLOOKUP(J8,'Entity Risk Master'!$D$5:$D$8,'Entity Risk Master'!$F$5:$F$8,"-",0,1) -> - | P8: 2. Use the countif function to determine the number of debit transactions above 50000
A9: 973498256 | B9: 925029911485208 | C9: THE SAMUEL TRADING COMPANY | D9: 1245 | E9: 140 | F9: DEBIT | G9: 45885 | H9: =IF(F9="DEBIT",E9,"-") -> 140 | I9: =IF(F9="CREDIT",E9,"-") -> - | K9: NEFT DEBIT | L9: - | M9: =_xlfn.XLOOKUP(J9,'Entity Risk Master'!$D$5:$D$8,'Entity Risk Master'!$F$5:$F$8,"-",0,1) -> - | P9: 3.Identify the top 3 transaction amounts for credits and debits.
A10: 973498256 | B10: 925029911485208 | C10: THE SAMUEL TRADING COMPANY | D10: 1245 | E10: 48000 | F10: DEBIT | G10: 45885 | H10: =IF(F10="DEBIT",E10,"-") -> 48000 | I10: =IF(F10="CREDIT",E10,"-") -> - | K10: NEFT DEBIT | L10: - | M10: =_xlfn.XLOOKUP(J10,'Entity Risk Master'!$D$5:$D$8,'Entity Risk Master'!$F$5:$F$8,"-",0,1) -> - | P10: 4. Use the VLOOKUP Function to classify internal transfer accounts based on Risk Level
A11: 973498256 | B11: 925029911485208 | C11: THE SAMUEL TRADING COMPANY | D11: 1245 | E11: 231 | F11: CREDIT | G11: 45885 | H11: =IF(F11="DEBIT",E11,"-") -> - | I11: =IF(F11="CREDIT",E11,"-") -> 231 | K11: IMPS TRANSFER CREDIT | L11: - | M11: =_xlfn.XLOOKUP(J11,'Entity Risk Master'!$D$5:$D$8,'Entity Risk Master'!$F$5:$F$8,"-",0,1) -> - | P11: 5.Use the XLOOKUP function to classify internal transfer accounts based on location.
A12: 973498256 | B12: 925029911485208 | C12: THE SAMUEL TRADING COMPANY | D12: 1245 | E12: 231 | F12: CREDIT | G12: 45885 | H12: =IF(F12="DEBIT",E12,"-") -> - | I12: =IF(F12="CREDIT",E12,"-") -> 231 | K12: NEFT CREDIT | L12: - | M12: =_xlfn.XLOOKUP(J12,'Entity Risk Master'!$D$5:$D$8,'Entity Risk Master'!$F$5:$F$8,"-",0,1) -> -
A13: 973498256 | B13: 925029911485208 | C13: THE SAMUEL TRADING COMPANY | D13: 1245 | E13: 188 | F13: CREDIT | G13: 45885 | H13: =IF(F13="DEBIT",E13,"-") -> - | I13: =IF(F13="CREDIT",E13,"-") -> 188 | K13: IMPS TRANSFER CREDIT | L13: - | M13: =_xlfn.XLOOKUP(J13,'Entity Risk Master'!$D$5:$D$8,'Entity Risk Master'!$F$5:$F$8,"-",0,1) -> -
A14: 973498256 | B14: 925029911485208 | C14: THE SAMUEL TRADING COMPANY | D14: 1245 | E14: 267 | F14: DEBIT | G14: 45885 | H14: =IF(F14="DEBIT",E14,"-") -> 267 | I14: =IF(F14="CREDIT",E14,"-") -> - | K14: NEFT DEBIT | L14: - | M14: =_xlfn.XLOOKUP(J14,'Entity Risk Master'!$D$5:$D$8,'Entity Risk Master'!$F$5:$F$8,"-",0,1) -> -
A15: 973498256 | B15: 925029911485208 | C15: THE SAMUEL TRADING COMPANY | D15: 1245 | E15: 321 | F15: CREDIT | G15: 45885 | H15: =IF(F15="DEBIT",E15,"-") -> - | I15: =IF(F15="CREDIT",E15,"-") -> 321 | K15: UPI CREDIT | L15: - | M15: =_xlfn.XLOOKUP(J15,'Entity Risk Master'!$D$5:$D$8,'Entity Risk Master'!$F$5:$F$8,"-",0,1) -> -
A16: 973498256 | B16: 925029911485208 | C16: THE SAMUEL TRADING COMPANY | D16: 1245 | E16: 200046 | F16: CREDIT | G16: 45885 | H16: =IF(F16="DEBIT",E16,"-") -> - | I16: =IF(F16="CREDIT",E16,"-") -> 200046 | K16: UPI CREDIT | L16: - | M16: =_xlfn.XLOOKUP(J16,'Entity Risk Master'!$D$5:$D$8,'Entity Risk Master'!$F$5:$F$8,"-",0,1) -> - | Q16: COUNT | R16: TOTAL TRANSACTIONS | S16: HIGH VALUE TRANSACTIONSABOVE Rs.50,000
A17: 973498256 | B17: 925029911485208 | C17: THE SAMUEL TRADING COMPANY | D17: 1245 | E17: 159609 | F17: DEBIT | G17: 45885 | H17: =IF(F17="DEBIT",E17,"-") -> 159609 | I17: =IF(F17="CREDIT",E17,"-") -> - | J17: =IF(K17="INTERNAL_TRF_DEBIT","SQL LOGISTICS") -> SQL LOGISTICS | K17: INTERNAL_TRF_DEBIT | L17: =VLOOKUP(J17,'Entity Risk Master'!$D$4:$I$8,2,FALSE) -> MEDIUM | M17: =_xlfn.XLOOKUP(J17,'Entity Risk Master'!$D$5:$D$8,'Entity Risk Master'!$F$5:$F$8,"-",0,1) -> MUMBAI | P17: DEBIT | Q17: =COUNT(H4:H161) -> 106 | R17: =COUNTA(H4:H161) -> 158 | S17: =COUNTIF(H4:H161,">50000") -> 4
A18: 973498256 | B18: 925029911485208 | C18: THE SAMUEL TRADING COMPANY | D18: 1245 | E18: 2567 | F18: DEBIT | G18: 45885 | H18: =IF(F18="DEBIT",E18,"-") -> 2567 | I18: =IF(F18="CREDIT",E18,"-") -> - | J18: =IF(K18="INTERNAL_TRF_DEBIT","SQL LOGISTICS") -> SQL LOGISTICS | K18: INTERNAL_TRF_DEBIT | L18: =VLOOKUP(J18,'Entity Risk Master'!$D$4:$I$8,2,FALSE) -> MEDIUM | M18: =_xlfn.XLOOKUP(J18,'Entity Risk Master'!$D$5:$D$8,'Entity Risk Master'!$F$5:$F$8,"-",0,1) -> MUMBAI | P18: CREDIT | Q18: =COUNT(I4:I161) -> 52 | R18: =COUNTA(I4:I161) -> 158 | S18: =COUNTIF(I4:I161,">50000") -> 7
A19: 973498256 | B19: 925029911485208 | C19: THE SAMUEL TRADING COMPANY | D19: 1245 | E19: 300043 | F19: CREDIT | G19: 45885 | H19: =IF(F19="DEBIT",E19,"-") -> - | I19: =IF(F19="CREDIT",E19,"-") -> 300043 | J19: =IF(K19="INTERNAL_TRF_CREDIT","RAMESH TRADING") -> RAMESH TRADING | K19: INTERNAL_TRF_CREDIT | L19: =VLOOKUP(J19,'Entity Risk Master'!$D$4:$I$8,2,FALSE) -> HIGH | M19: =_xlfn.XLOOKUP(J19,'Entity Risk Master'!$D$5:$D$8,'Entity Risk Master'!$F$5:$F$8,"-",0,1) -> NAGERCOIL
A20: 973498256 | B20: 925029911485208 | C20: THE SAMUEL TRADING COMPANY | D20: 1245 | E20: 38140 | F20: DEBIT | G20: 45885 | H20: =IF(F20="DEBIT",E20,"-") -> 38140 | I20: =IF(F20="CREDIT",E20,"-") -> - | K20: NEFT DEBIT | L20: - | M20: =_xlfn.XLOOKUP(J20,'Entity Risk Master'!$D$5:$D$8,'Entity Risk Master'!$F$5:$F$8,"-",0,1) -> -
A21: 973498256 | B21: 925029911485208 | C21: THE SAMUEL TRADING COMPANY | D21: 1245 | E21: 87744 | F21: DEBIT | G21: 45885 | H21: =IF(F21="DEBIT",E21,"-") -> 87744 | I21: =IF(F21="CREDIT",E21,"-") -> - | K21: NEFT DEBIT | L21: - | M21: =_xlfn.XLOOKUP(J21,'Entity Risk Master'!$D$5:$D$8,'Entity Risk Master'!$F$5:$F$8,"-",0,1) -> - | P21: DEBIT | Q21: CREDIT
A22: 973498256 | B22: 925029911485208 | C22: THE SAMUEL TRADING COMPANY | D22: 1245 | E22: 1570 | F22: DEBIT | G22: 45885 | H22: =IF(F22="DEBIT",E22,"-") -> 1570 | I22: =IF(F22="CREDIT",E22,"-") -> - | K22: NEFT DEBIT | L22: - | M22: =_xlfn.XLOOKUP(J22,'Entity Risk Master'!$D$5:$D$8,'Entity Risk Master'!$F$5:$F$8,"-",0,1) -> - | O22: 1st Largest Value | P22: =LARGE(H4:H161,1) -> 159609 | Q22: =LARGE(I4:I161,1) -> 300043
A23: 973498256 | B23: 925029911485208 | C23: THE SAMUEL TRADING COMPANY | D23: 1245 | E23: 300043 | F23: CREDIT | G23: 45885 | H23: =IF(F23="DEBIT",E23,"-") -> - | I23: =IF(F23="CREDIT",E23,"-") -> 300043 | K23: IMPS TRANSFER CREDIT | L23: - | M23: =_xlfn.XLOOKUP(J23,'Entity Risk Master'!$D$5:$D$8,'Entity Risk Master'!$F$5:$F$8,"-",0,1) -> - | O23: 2nd Largest Value | P23: =LARGE(H5:H162,2) -> 156934 | Q23: =LARGE(I4:I162,3) -> 200046
A24: 973498256 | B24: 925029911485208 | C24: THE SAMUEL TRADING COMPANY | D24: 1245 | E24: 38140 | F24: DEBIT | G24: 45885 | H24: =IF(F24="DEBIT",E24,"-") -> 38140 | I24: =IF(F24="CREDIT",E24,"-") -> - | K24: IMPS TRANSFER DEBIT | L24: - | M24: =_xlfn.XLOOKUP(J24,'Entity Risk Master'!$D$5:$D$8,'Entity Risk Master'!$F$5:$F$8,"-",0,1) -> - | O24: 3rd Largest Value | P24: =LARGE(H6:H163,3) -> 87744 | Q24: =LARGE(I4:I163,4) -> 103378
A25: 973498256 | B25: 925029911485208 | C25: THE SAMUEL TRADING COMPANY | D25: 1245 | E25: 87744 | F25: DEBIT | G25: 45885 | H25: =IF(F25="DEBIT",E25,"-") -> 87744 | I25: =IF(F25="CREDIT",E25,"-") -> - | K25: IMPS TRANSFER DEBIT | L25: - | M25: =_xlfn.XLOOKUP(J25,'Entity Risk Master'!$D$5:$D$8,'Entity Risk Master'!$F$5:$F$8,"-",0,1) -> -
A26: 973498256 | B26: 925029911485208 | C26: THE SAMUEL TRADING COMPANY | D26: 1245 | E26: 275 | F26: DEBIT | G26: 45885 | H26: =IF(F26="DEBIT",E26,"-") -> 275 | I26: =IF(F26="CREDIT",E26,"-") -> - | K26: IMPS TRANSFER DEBIT | L26: - | M26: =_xlfn.XLOOKUP(J26,'Entity Risk Master'!$D$5:$D$8,'Entity Risk Master'!$F$5:$F$8,"-",0,1) -> -
A27: 973498256 | B27: 925029911485208 | C27: THE SAMUEL TRADING COMPANY | D27: 1245 | E27: 1283 | F27: DEBIT | G27: 45885 | H27: =IF(F27="DEBIT",E27,"-") -> 1283 | I27: =IF(F27="CREDIT",E27,"-") -> - | K27: IMPS TRANSFER DEBIT | L27: - | M27: =_xlfn.XLOOKUP(J27,'Entity Risk Master'!$D$5:$D$8,'Entity Risk Master'!$F$5:$F$8,"-",0,1) -> - | Q27: TXN REMARKS | R27: TOTAL AMOUNT
A28: 973498256 | B28: 925029911485208 | C28: THE SAMUEL TRADING COMPANY | D28: 1245 | E28: 275 | F28: CREDIT | G28: 45885 | H28: =IF(F28="DEBIT",E28,"-") -> - | I28: =IF(F28="CREDIT",E28,"-") -> 275 | K28: NEFT CREDIT | L28: - | M28: =_xlfn.XLOOKUP(J28,'Entity Risk Master'!$D$5:$D$8,'Entity Risk Master'!$F$5:$F$8,"-",0,1) -> -
A29: 973498256 | B29: 925029911485208 | C29: THE SAMUEL TRADING COMPANY | D29: 1245 | E29: 100 | F29: CREDIT | G29: 45885 | H29: =IF(F29="DEBIT",E29,"-") -> - | I29: =IF(F29="CREDIT",E29,"-") -> 100 | K29: NEFT CREDIT | L29: - | M29: =_xlfn.XLOOKUP(J29,'Entity Risk Master'!$D$5:$D$8,'Entity Risk Master'!$F$5:$F$8,"-",0,1) -> - | Q29: DD_PROCEEDS | R29: =SUMIF($K:$K,Q29,$I:$I) -> 50000
A30: 973498256 | B30: 925029911485208 | C30: THE SAMUEL TRADING COMPANY | D30: 1245 | E30: 45612 | F30: DEBIT | G30: 45885 | H30: =IF(F30="DEBIT",E30,"-") -> 45612 | I30: =IF(F30="CREDIT",E30,"-") -> - | J30: =IF(K30="INTERNAL_TRF_DEBIT","SQL LOGISTICS") -> SQL LOGISTICS | K30: INTERNAL_TRF_DEBIT | L30: =VLOOKUP(J30,'Entity Risk Master'!$D$4:$I$8,2,FALSE) -> MEDIUM | M30: =_xlfn.XLOOKUP(J30,'Entity Risk Master'!$D$5:$D$8,'Entity Risk Master'!$F$5:$F$8,"-",0,1) -> MUMBAI | Q30: INTERNAL_TRF_CREDIT | R30: =SUMIF($K:$K,Q30,$I:$I) -> 730260
A31: 973498256 | B31: 925029911485208 | C31: THE SAMUEL TRADING COMPANY | D31: 1245 | E31: 21548 | F31: DEBIT | G31: 45885 | H31: =IF(F31="DEBIT",E31,"-") -> 21548 | I31: =IF(F31="CREDIT",E31,"-") -> - | J31: =IF(K31="INTERNAL_TRF_DEBIT","SQL LOGISTICS") -> SQL LOGISTICS | K31: INTERNAL_TRF_DEBIT | L31: =VLOOKUP(J31,'Entity Risk Master'!$D$4:$I$8,2,FALSE) -> MEDIUM | M31: =_xlfn.XLOOKUP(J31,'Entity Risk Master'!$D$5:$D$8,'Entity Risk Master'!$F$5:$F$8,"-",0,1) -> MUMBAI | Q31: IMPS TRANSFER CREDIT | R31: =SUMIF($K:$K,Q31,$I:$I) -> 300462
A32: 973498256 | B32: 925029911485208 | C32: THE SAMUEL TRADING COMPANY | D32: 1245 | E32: 258 | F32: DEBIT | G32: 45885 | H32: =IF(F32="DEBIT",E32,"-") -> 258 | I32: =IF(F32="CREDIT",E32,"-") -> - | J32: =IF(K32="INTERNAL_TRF_DEBIT","SQL LOGISTICS") -> SQL LOGISTICS | K32: INTERNAL_TRF_DEBIT | L32: =VLOOKUP(J32,'Entity Risk Master'!$D$4:$I$8,2,FALSE) -> MEDIUM | M32: =_xlfn.XLOOKUP(J32,'Entity Risk Master'!$D$5:$D$8,'Entity Risk Master'!$F$5:$F$8,"-",0,1) -> MUMBAI | Q32: NEFT CREDIT | R32: =SUMIF($K:$K,Q32,$I:$I) -> 38389
A33: 973498256 | B33: 925029911485208 | C33: THE SAMUEL TRADING COMPANY | D33: 1245 | E33: 21452 | F33: DEBIT | G33: 45887 | H33: =IF(F33="DEBIT",E33,"-") -> 21452 | I33: =IF(F33="CREDIT",E33,"-") -> - | K33: RTGS DEBIT | L33: - | M33: =_xlfn.XLOOKUP(J33,'Entity Risk Master'!$D$5:$D$8,'Entity Risk Master'!$F$5:$F$8,"-",0,1) -> - | Q33: RTGS CREDIT | R33: =SUMIF($K:$K,Q33,$I:$I) -> 124198
A34: 973498256 | B34: 925029911485208 | C34: THE SAMUEL TRADING COMPANY | D34: 1245 | E34: 8524 | F34: DEBIT | G34: 45887 | H34: =IF(F34="DEBIT",E34,"-") -> 8524 | I34: =IF(F34="CREDIT",E34,"-") -> - | K34: ATM WITHDRAWAL | L34: - | M34: =_xlfn.XLOOKUP(J34,'Entity Risk Master'!$D$5:$D$8,'Entity Risk Master'!$F$5:$F$8,"-",0,1) -> - | Q34: CASH DEPOSIT | R34: =SUMIF($K:$K,Q34,$I:$I) -> 28265
A35: 973498256 | B35: 925029911485208 | C35: THE SAMUEL TRADING COMPANY | D35: 1245 | E35: 22674 | F35: CREDIT | G35: 45887 | H35: =IF(F35="DEBIT",E35,"-") -> - | I35: =IF(F35="CREDIT",E35,"-") -> 22674 | K35: UPI CREDIT | L35: - | M35: =_xlfn.XLOOKUP(J35,'Entity Risk Master'!$D$5:$D$8,'Entity Risk Master'!$F$5:$F$8,"-",0,1) -> - | Q35: UPI CREDIT | R35: =SUMIF($K:$K,Q35,$I:$I) -> 474287
A36: 973498256 | B36: 925029911485208 | C36: THE SAMUEL TRADING COMPANY | D36: 1245 | E36: 1541 | F36: DEBIT | G36: 45887 | H36: =IF(F36="DEBIT",E36,"-") -> 1541 | I36: =IF(F36="CREDIT",E36,"-") -> - | J36: =IF(K36="INTERNAL_TRF_DEBIT","SQL LOGISTICS") -> SQL LOGISTICS | K36: INTERNAL_TRF_DEBIT | L36: =VLOOKUP(J36,'Entity Risk Master'!$D$4:$I$8,2,FALSE) -> MEDIUM | M36: =_xlfn.XLOOKUP(J36,'Entity Risk Master'!$D$5:$D$8,'Entity Risk Master'!$F$5:$F$8,"-",0,1) -> MUMBAI | Q36: TOTAL CREDITS | R36: =SUM(R29:R35) -> 1745861
A37: 973498256 | B37: 925029911485208 | C37: THE SAMUEL TRADING COMPANY | D37: 1245 | E37: 8123 | F37: DEBIT | G37: 45887 | H37: =IF(F37="DEBIT",E37,"-") -> 8123 | I37: =IF(F37="CREDIT",E37,"-") -> - | J37: =IF(K37="INTERNAL_TRF_DEBIT","SQL LOGISTICS") -> SQL LOGISTICS | K37: INTERNAL_TRF_DEBIT | L37: =VLOOKUP(J37,'Entity Risk Master'!$D$4:$I$8,2,FALSE) -> MEDIUM | M37: =_xlfn.XLOOKUP(J37,'Entity Risk Master'!$D$5:$D$8,'Entity Risk Master'!$F$5:$F$8,"-",0,1) -> MUMBAI
A38: 973498256 | B38: 925029911485208 | C38: THE SAMUEL TRADING COMPANY | D38: 1245 | E38: =23962+78467 -> 102429 | F38: CREDIT | G38: 45887 | H38: =IF(F38="DEBIT",E38,"-") -> - | I38: =IF(F38="CREDIT",E38,"-") -> 102429 | J38: =IF(K38="INTERNAL_TRF_CREDIT","RAMESH TRADING") -> RAMESH TRADING | K38: INTERNAL_TRF_CREDIT | L38: =VLOOKUP(J38,'Entity Risk Master'!$D$4:$I$8,2,FALSE) -> HIGH | M38: =_xlfn.XLOOKUP(J38,'Entity Risk Master'!$D$5:$D$8,'Entity Risk Master'!$F$5:$F$8,"-",0,1) -> NAGERCOIL | Q38: BANK CHARGES | R38: =SUMIF($K:$K,Q38,$H:$H) -> 110567
A39: 973498256 | B39: 925029911485208 | C39: THE SAMUEL TRADING COMPANY | D39: 1245 | E39: 15219 | F39: CREDIT | G39: 45887 | H39: =IF(F39="DEBIT",E39,"-") -> - | I39: =IF(F39="CREDIT",E39,"-") -> 15219 | K39: NEFT CREDIT | L39: - | M39: =_xlfn.XLOOKUP(J39,'Entity Risk Master'!$D$5:$D$8,'Entity Risk Master'!$F$5:$F$8,"-",0,1) -> - | Q39: INTERNAL_TRF_DEBIT | R39: =SUMIF($K:$K,Q39,$H:$H) -> 657694
A40: 973498256 | B40: 925029911485208 | C40: THE SAMUEL TRADING COMPANY | D40: 1245 | E40: 5731 | F40: CREDIT | G40: 45887 | H40: =IF(F40="DEBIT",E40,"-") -> - | I40: =IF(F40="CREDIT",E40,"-") -> 5731 | K40: RTGS CREDIT | L40: - | M40: =_xlfn.XLOOKUP(J40,'Entity Risk Master'!$D$5:$D$8,'Entity Risk Master'!$F$5:$F$8,"-",0,1) -> - | Q40: NEFT DEBIT | R40: =SUMIF($K:$K,Q40,$H:$H) -> 386376
A41: 973498256 | B41: 925029911485208 | C41: THE SAMUEL TRADING COMPANY | D41: 1245 | E41: 9605 | F41: DEBIT | G41: 45887 | H41: =IF(F41="DEBIT",E41,"-") -> 9605 | I41: =IF(F41="CREDIT",E41,"-") -> - | K41: BANK CHARGES | L41: - | M41: =_xlfn.XLOOKUP(J41,'Entity Risk Master'!$D$5:$D$8,'Entity Risk Master'!$F$5:$F$8,"-",0,1) -> - | Q41: IMPS TRANSFER DEBIT | R41: =SUMIF($K:$K,Q41,$H:$H) -> 127442
...

Sheet Summarized Transaction Details
B3: Column Labels
B4: Sum of CREDIT | C4: Sum of DEBIT | D4: Total Sum of CREDIT | E4: Total Sum of DEBIT
B5: Aug | C5: Aug
A6: Row Labels
A7: AJAZ AGRO | B7: 0 | C7: 304560 | D7: 0 | E7: 304560
A8: OTHER | B8: 0 | C8: 800 | D8: 0 | E8: 800
A9: RAMESH TRADING | B9: 345087 | C9: 0 | D9: 345087 | E9: 0
A10: SQL LOGISTICS | B10: 0 | C10: 353134 | D10: 0 | E10: 353134
A11: VIJAY SALES | B11: 85130 | C11: 0 | D11: 85130 | E11: 0
A12: (blank) | B12: 1265644 | C12: 1087367 | D12: 1265644 | E12: 1087367
A13: Grand Total | B13: 1695861 | C13: 1745861 | D13: 1695861 | E13: 1745861
X21: =GETPIVOTDATA("Sum of DEBIT",$A$3)-GETPIVOTDATA("Sum of CREDIT",$A$3) -> 50000
X22: =X21/4 -> 12500

Sheet Entity Risk Master
C4: TRANSACTION TYPE | D4: PAYEE NAME | E4: RISK LEVEL | F4: CITY | G4: STATE | H4: MULE HOTSPOT | I4: BRANCH CATEGORY | J4: BRANCH INPUTS
C5: INTERNAL CREDIT | D5: RAMESH TRADING | E5: HIGH | F5: NAGERCOIL | G5: TAMIL NADU | H5: YES | I5: SHELL ENTITY | J5: DOCUMENTS VERIFIED, HOWEVER, THE COMPANY NOT INVOLVED IN ANY TRADING BUSINESS AS CLAIMED, EDD WAS NEGATIVE AND DIRECTORS ABSCONDING
C6: INTERNAL DEBIT | D6: SQL LOGISTICS | E6: MEDIUM | F6: MUMBAI | G6: MAHARASHTRA | H6: NA | I6: LOGISTICS | J6: THE DIRECTORS CLAIMED TO BE A VICTIM OF FRAUD. MULTIPLE STATUTORY NOTICES RECEIVED, HOWEVER NO DOCUMENTARY PROOF PROVIDED BY CUSTOMER
C7: INTERNAL CREDIT | D7: VIJAY SALES | E7: LOW | F7: RAICHUR | G7: KARNATAKA | H7: NA | I7: MOBILE SALES AND SERVICES | J7: THE PROPRIETOR IS A VICTIM OF ONLINE DIGITAL ARREST COURT, HE HAS LOST HIS AMOUNT OF RS.10,00,000 AND HAS RAISED COMPLAINTS WITH CYBER CELL
C8: INTERNAL DEBIT | D8: AJAZ AGRO | E8: HIGH | F8: GUNTUR | G8: ANDHRA PRADESH | H8: YES | I8: AGRO FERTILIZERS | J8: PARTNERS INVOLVED IN ROUTING OF FRAUDULENT TRANSACTIONS, MULTIPLE NOTICES RECEIVED AND PARTNERS IN POLICE CUSTODY

Sheet Mule Hotspot Map
C5: CITY | D5: STATE | E5: RISK SCORE | F5: ENTITY NAMES
C6: NAGERCOIL | D6: TAMIL NADU | E6: 100 | F6: RAMESH TRADING
C7: MUMBAI | D7: MAHARASHTRA | E7: 80 | F7: SQL LOGISTICS
C8: GUNTUR | D8: ANDHRA PRADESH | E8: 90 | F8: AJAZ AGRO
C9: RAICHUR | D9: KARNATAKA | E9: 80 | F9: VIJAY SALES
C13: Bank has significant presence In the digital payments and online transactions domain.Making banking more accesible across the country.But this rapid expansion has also opened new avenues for cybercriminals. A disturbing trend gaining momentum is the use of "Mule accounts" in Tier 2 and Tier 3 cities. Exploited to launder money from online scams, frauds and illegal activities.
C19: Existing Bank Controls *Digital Transactions Monitoring *EDD and Field Verification *Fraud Escalation SOPs *Dedicated Fraud Investigations Teams.

Sheet Dashboard

Sheet SQL Query Details
B4: QUERY OBJECTIVE | C4: SQL QUERY | D4: OUTPUT | E4: INVESTIGATION INSIGHT
B5: Detect accounts with unusually high transaction count. | C5: SELECT `PAYEE NAME`, COUNT(*) AS total_transactions FROM `sql samuel trading company data` WHERE `PAYEE NAME` <>'' and `PAYEE NAME` <>'OTHER' GROUP BY `PAYEE NAME` HAVING COUNT(*) > 8;
B6: Rapid Inward and Outward Movement | C6: SELECT `PAYEE NAME`, SUM(CASE WHEN `TRANSACTION TYPE` = 'CREDIT' THEN `TRANSACTION AMOUNT` ELSE 0 END) AS total_credit, SUM(CASE WHEN `TRANSACTION TYPE` = 'DEBIT' THEN `TRANSACTION AMOUNT` ELSE 0 END) AS total_debit FROM `sql samuel trading company data` WHERE `PAYEE NAME` IS NOT NULL AND `PAYEE NAME` <> '' AND `PAYEE NAME` <> 'OTHER' GROUP BY `PAYEE NAME` HAVING total_credit > 50000 or total_debit > 50000;
B7: Structuring Detection | C7: SELECT `PAYEE NAME`, `TRANSACTION DATE`, COUNT(*) AS cash_deposits FROM `sql samuel trading company data` WHERE `TXN REMARKS`='INTERNAL_TRF_CREDIT' AND `TRANSACTION AMOUNT` BETWEEN 3000 AND 80000 GROUP BY `PAYEE NAME`, `TRANSACTION DATE`;
B8: Transaction typewise classification | C8: SELECT `TXN REMARKS`, SUM(`TRANSACTION AMOUNT`) AS total_amount FROM `sql samuel trading company data` GROUP BY `TXN REMARKS` ORDER BY total_amount DESC;
B9: Geographic Hotspot Analysis | C9: SELECT CITY, count(DISTINCT `PAYEE NAME`) AS suspicious_entity_count FROM `sql samuel trading company data` WHERE CITY<> '-' GROUP BY CITY
B10: Top High-Risk Entities | C10: SELECT `RISK LEVEL`, COUNT(DISTINCT `PAYEE NAME`) AS suspicious_entity_count, GROUP_CONCAT(DISTINCT `PAYEE NAME` ORDER BY `PAYEE NAME` SEPARATOR ', ') AS entity_names FROM `sql samuel trading company data` WHERE `PAYEE NAME` IS NOT NULL AND `PAYEE NAME` <> '' AND `PAYEE NAME` <> 'OTHER' GROUP BY `RISK LEVEL`;

Sheet ..
M3: FINANCIAL CRIME TRANSACTION MONITORING DASHBOARD - THE SAMUEL TRADING COMPANY
M5: TOTAL TRANSACTIONS 158 | Q5: Transacion Summary | U5: High Value Transactions
Q6: TXN REMARKS | R6: TOTAL AMOUNT | V6: DEBIT | W6: CREDIT
Q7: CREDITS | U7: 1st Largest Value | V7: 159609 | W7: 300043
Q8: DD_PROCEEDS | R8: 50000 | U8: 2nd Largest Value | V8: 156934 | W8: 200046
Q9: INTERNAL_TRF_CREDIT | R9: 730260 | U9: 3rd Largest Value | V9: 87744 | W9: 103378
M10: TOTAL DEBITS ₹17,45,861 | Q10: IMPS TRANSFER CREDIT | R10: 300462
Q11: NEFT CREDIT | R11: 38389
Q12: RTGS CREDIT | R12: 124198 | U12: Key Findings
Q13: CASH DEPOSIT | R13: 28265 | U13: * Mule hotspots identified in Guntur and Nagercoil. The branches confirmed the modus operandi. * The EDD and field verifications conducted by the branches were not satisfactory. The other entities were not able to provide documentary proofs. Hence, there claims could not be verified. * The Pattern of the transaction confirms fraudulent transactions being routed through the account. * Customer is not contactable and branch confirmed that the customer is in Police custody.
Q14: UPI CREDIT | R14: 474287
Q15: TOTAL CREDITS | R15: 1745861
M16: TOTAL CREDITS ₹17,45,861 | Q16: DEBITS
Q17: BANK CHARGES | R17: 110567
Q18: INTERNAL_TRF_DEBIT | R18: 657694
Q19: NEFT DEBIT | R19: 386376
Q20: IMPS TRANSFER DEBIT | R20: 127442
Q21: RTGS DEBIT | R21: 209789
M22: HIGH RISK ENTITIES 2 | Q22: ATM WITHDRAWAL | R22: 59171
Q23: UPI DEBIT | R23: 194822
Q24: TOTAL DEBITS | R24: 1745861
M28: MULE HOTSPOTS 2 | Q28: RISK TABLE
Q29: RISK | R29: COUNT
Q30: HIGH | R30: 2
Q31: MEDIUM | R31: 1
Q32: LOW | R32: 1
Q36: Linkend Entity | R36: Transaction Type
Q37: RAMESH TRADING | R37: INTERNAL TRF CREDIT
Q38: SQL LOGISTICS | R38: INTERNAL TRF DEBIT
Q39: VIJAY SALES | R39: INTERNAL TRF CREDIT
Q40: AJAZ AGRO | R40: INTERNAL TRF DEBIT
